Traceback (most recent call last):
  File "/app/manage.py", line 23, in <module>
    main()
  File "/app/manage.py", line 19, in main
    execute_from_command_line(sys.argv)
  File "/usr/local/lib/python3.10/site-packages/django/core/management/__init__.py", line 446, in execute_from_command_line
    utility.execute()
  File "/usr/local/lib/python3.10/site-packages/django/core/management/__init__.py", line 440, in execute
    self.fetch_command(subcommand).run_from_argv(self.argv)
  File "/usr/local/lib/python3.10/site-packages/django/core/management/base.py", line 414, in run_from_argv
    self.execute(*args, **cmd_options)
  File "/usr/local/lib/python3.10/site-packages/django/core/management/base.py", line 460, in execute
    output = self.handle(*args, **options)
  File "/usr/local/lib/python3.10/site-packages/django_crontab/management/commands/crontab.py", line 29, in handle
    Crontab().run_job(options['jobhash'])
  File "/usr/local/lib/python3.10/site-packages/django_crontab/crontab.py", line 126, in run_job
    job = self.__get_job_by_hash(job_hash)
  File "/usr/local/lib/python3.10/site-packages/django_crontab/crontab.py", line 171, in __get_job_by_hash
    raise RuntimeError(
RuntimeError: No job with hash 9d5a0cf6564a9e86eec8f5449840e7cf found. It seems the crontab is out of sync with your settings.CRONJOBS. Run "python manage.py crontab add" again to resolve this issue!
